<?xml version='1.0'?>
<sdf version="1.4">
<model name="base">
	<pose>0 0 0.1 0 0 0</pose>
	<static>false</static>
		<link name="link_base">
			<pose>0 0 0 0 0 0</pose>
			<self_collide>1</self_collide>
			<inertial>
				<pose>-0.120031 0.0898494 0.0255337 0 0 0</pose>
				<mass>0.305361</mass>
				<inertia>
					<ixx>0.001052</ixx>
					<ixy>-0.00000003171</ixy>
					<ixz>-0.000000321256</ixz>
					<iyy>0.001018</iyy>
					<iyz>-0.00003391</iyz>
					<izz>0.001780</izz>
				</inertia>
			</inertial>
			<collision name="collision">
				<geometry>
					<mesh>
						<uri>model://base/kame_assem_4.stl</uri>
					</mesh>
				</geometry>
			</collision>
			<visual name="visual">
				<geometry>
					<mesh>
						<uri>model://base/kame_assem_4_ad.stl</uri>
					</mesh>
				</geometry>
			</visual>
		</link>

		<link name="a_slider_jiku">
			<pose>-0.0727 0.1125 0.013 0 0 0</pose>
			<self_collide>1</self_collide>
			<inertial>
				<pose>-0.0325 0.000000000000000000648431 0.000000000000615133 0 0 0</pose>
				<mass>0.004623</mass>
				<inertia>
					<ixx>0.000000020124</ixx>
					<ixy>0</ixy>
					<ixz>0</ixz>
					<iyy>0.000001441072</iyy>
					<iyz>0</iyz>
					<izz>0.000001441072</izz>
				</inertia>
			</inertial>
			<collision name="collision">
				<geometry>
					<mesh>
						<uri>model://base/slider_jiku.stl</uri>
					</mesh>
				</geometry>
				<surface>
					<friction>
						<torsional>
							<coefficient>0</coefficient>
						</torsional>
						<ode>
							<mu>0</mu>
							<mu2>0</mu2>
							<slip1>1.0</slip1>
							<slip2>1.0</slip2>
						</ode>
					</friction>
				</surface>
			</collision>
			<visual name="visual">
				<geometry>
					<mesh>
						<uri>model://base/slider_jiku_ad.stl</uri>
					</mesh>
				</geometry>
			</visual>
		</link>

		<joint name="base_to_slider_a" type="revolute">
			<pose>0 0 0 0 0 0</pose>
			<child>a_slider_jiku</child>
			<parent>link_base</parent>
			<axis>
				<xyz>1 0 0</xyz>
				<use_parent_model_frame>1</use_parent_model_frame>
			</axis>
		</joint>

		<link name="d_slider_jiku">
			<pose>-0.0727 0.0225 0.013 0 0 0</pose>
			<self_collide>1</self_collide>
			<inertial>
				<pose>-0.0325 0.000000000000000000648431 0.000000000000615133 0 0 0</pose>
				<mass>0.004623</mass>
				<inertia>
					<ixx>0.000000020124</ixx>
					<ixy>0</ixy>
					<ixz>0</ixz>
					<iyy>0.000001441072</iyy>
					<iyz>0</iyz>
					<izz>0.000001441072</izz>
				</inertia>
			</inertial>
			<collision name="collision">
				<geometry>
					<mesh>
						<uri>model://base/slider_jiku.stl</uri>
					</mesh>
				</geometry>
				<surface>
					<friction>
						<torsional>
							<coefficient>0</coefficient>
						</torsional>
						<ode>
							<mu>0</mu>
							<mu2>0</mu2>
							<slip1>1.0</slip1>
							<slip2>1.0</slip2>
						</ode>
					</friction>
				</surface>
			</collision>
			<visual name="visual">
				<geometry>
					<mesh>
						<uri>model://base/slider_jiku_ad.stl</uri>
					</mesh>
				</geometry>
			</visual>
		</link>

		<joint name="base_to_slider_d" type="revolute">
			<pose>0 0 0 0 0 0</pose>
			<child>d_slider_jiku</child>
			<parent>link_base</parent>
			<axis>
				<xyz>1 0 0</xyz>
				<use_parent_model_frame>1</use_parent_model_frame>
			</axis>
		</joint>

		<link name="b_slider_jiku">
			<pose>-0.1673 0.1125 0.013 0 0 0</pose>
			<self_collide>1</self_collide>
			<inertial>
				<pose>-0.0325 0.000000000000000000648431 -0.000000000000615133 0 0 0</pose>
				<mass>0.004623</mass>
				<inertia>
					<ixx>0.000000020124</ixx>
					<ixy>0</ixy>
					<ixz>0</ixz>
					<iyy>0.000001441072</iyy>
					<iyz>0</iyz>
					<izz>0.000001441072</izz>
				</inertia>
			</inertial>
			<collision name="collision">
				<geometry>
					<mesh>
						<uri>model://base/slider_jiku_2.stl</uri>
					</mesh>
				</geometry>
				<surface>
					<friction>
						<torsional>
							<coefficient>0</coefficient>
						</torsional>
						<ode>
							<mu>0</mu>
							<mu2>0</mu2>
							<slip1>1.0</slip1>
							<slip2>1.0</slip2>
						</ode>
					</friction>
				</surface>
			</collision>
			<visual name="visual">
				<geometry>
					<mesh>
						<uri>model://base/slider_jiku_2_ad.stl</uri>
					</mesh>
				</geometry>
			</visual>
		</link>

		<joint name="base_to_slider_b" type="revolute">
			<pose>0 0 0 0 0 0</pose>
			<child>b_slider_jiku</child>
			<parent>link_base</parent>
			<axis>
				<xyz>1 0 0</xyz>
				<use_parent_model_frame>1</use_parent_model_frame>
			</axis>
		</joint>

		<link name="c_slider_jiku">
			<pose>-0.1673 0.0225 0.013 0 0 0</pose>
			<self_collide>1</self_collide>
			<inertial>
				<pose>-0.0325 0.000000000000000000648431 -0.000000000000615133 0 0 0</pose>
				<mass>0.004623</mass>
				<inertia>
					<ixx>0.000000020124</ixx>
					<ixy>0</ixy>
					<ixz>0</ixz>
					<iyy>0.000001441072</iyy>
					<iyz>0</iyz>
					<izz>0.000001441072</izz>
				</inertia>
			</inertial>
			<collision name="collision">
				<geometry>
					<mesh>
						<uri>model://base/slider_jiku_2.stl</uri>
					</mesh>
				</geometry>
				<surface>
					<friction>
						<torsional>
							<coefficient>0</coefficient>
						</torsional>
						<ode>
							<mu>0</mu>
							<mu2>0</mu2>
							<slip1>1.0</slip1>
							<slip2>1.0</slip2>
						</ode>
					</friction>
				</surface>
			</collision>
			<visual name="visual">
				<geometry>
					<mesh>
						<uri>model://base/slider_jiku_2_ad.stl</uri>
					</mesh>
				</geometry>
			</visual>
		</link>

		<joint name="base_to_slider_c" type="revolute">
			<pose>0 0 0 0 0 0</pose>
			<child>c_slider_jiku</child>
			<parent>link_base</parent>
			<axis>
				<xyz>1 0 0</xyz>
				<use_parent_model_frame>1</use_parent_model_frame>
			</axis>
		</joint>

		<link name="a_crank_link">
			<pose>-0.0777 0.1375 0.013 0 0 0</pose>
			<self_collide>1</self_collide>
			<inertial>
				<pose>0.0374352 -0.000548426 -0.00311027 0 0 0</pose>
				<mass>0.094516</mass>
				<inertia>
					<ixx>0.00001618</ixx>
					<ixy>0.000004583807</ixy>
					<ixz>0.000000791555</ixz>
					<iyy>0.00002918</iyy>
					<iyz>-0.000000161333</iyz>
					<izz>0.00003007</izz>
				</inertia>
			</inertial>
			<collision name="collision">
				<geometry>
					<mesh>
						<uri>model://base/crank1.stl</uri>
					</mesh>
				</geometry>
			</collision>
			<visual name="visual">
				<geometry>
					<mesh>
						<uri>model://base/crank1_ad.stl</uri>
					</mesh>
				</geometry>
			</visual>
		</link>

		<joint name="base_to_a" type="revolute">
			<pose>0 0 0 0 0 0</pose>
			<child>a_crank_link</child>
			<parent>link_base</parent>
			<axis>
				<xyz>1 0 0</xyz>
				<use_parent_model_frame>1</use_parent_model_frame>
			</axis>
		</joint>

		<link name="b_crank_link">
			<pose>-0.1623 0.1375 0.013 0 0 0</pose>
			<self_collide>1</self_collide>
			<inertial>
				<pose>0.0374352 0.00000000035296 -0.00315826 0 0 0</pose>
				<mass>0.094516</mass>
				<inertia>
					<ixx>0.00001618</ixx>
					<ixy>-0.00000465162</ixy>
					<ixz>0.000000016441</ixz>
					<iyy>0.00002915</iyy>
					<iyz>0.0000000000001060</iyz>
					<izz>0.00003010</izz>
				</inertia>
			</inertial>
			<collision name="collision">
				<geometry>
					<mesh>
						<uri>model://base/crank2.stl</uri>
					</mesh>
				</geometry>
			</collision>
			<visual name="visual">
				<geometry>
					<mesh>
						<uri>model://base/crank2_ad.stl</uri>
					</mesh>
				</geometry>
			</visual>
		</link>

		<joint name="base_to_b" type="revolute">
			<pose>0 0 0 0 0 0</pose>
			<child>b_crank_link</child>
			<parent>link_base</parent>
			<axis>
				<xyz>1 0 0</xyz>
				<use_parent_model_frame>1</use_parent_model_frame>
			</axis>
		</joint>

		<link name="c_crank_link">
			<pose>-0.1623 0.0475 0.013 0 0 0</pose>
			<self_collide>1</self_collide>
			<inertial>
				<pose>0.0374352 0.00000000035296 -0.00315826 0 0 0</pose>
				<mass>0.094516</mass>
				<inertia>
					<ixx>0.00001618</ixx>
					<ixy>-0.00000465162</ixy>
					<ixz>0.000000016441</ixz>
					<iyy>0.00002915</iyy>
					<iyz>0.0000000000001060</iyz>
					<izz>0.00003010</izz>
				</inertia>
			</inertial>
			<collision name="collision">
				<geometry>
					<mesh>
						<uri>model://base/crank2.stl</uri>
					</mesh>
				</geometry>
			</collision>
			<visual name="visual">
				<geometry>
					<mesh>
						<uri>model://base/crank2_ad.stl</uri>
					</mesh>
				</geometry>
			</visual>
		</link>

		<joint name="base_to_c" type="revolute">
			<pose>0 0 0 0 0 0</pose>
			<child>c_crank_link</child>
			<parent>link_base</parent>
			<axis>
				<xyz>1 0 0</xyz>
				<use_parent_model_frame>1</use_parent_model_frame>
			</axis>
		</joint>

		<link name="d_crank_link">
			<pose>-0.0777 0.0475 0.013 0 0 0</pose>
			<self_collide>1</self_collide>
			<inertial>
				<pose>0.0374352 -0.000548426 -0.00311027 0 0 0</pose>
				<mass>0.094516</mass>
				<inertia>
					<ixx>0.00001618</ixx>
					<ixy>0.000004583807</ixy>
					<ixz>0.000000791555</ixz>
					<iyy>0.00002918</iyy>
					<iyz>-0.000000161333</iyz>
					<izz>0.00003007</izz>
				</inertia>
			</inertial>
			<collision name="collision">
				<geometry>
					<mesh>
						<uri>model://base/crank1.stl</uri>
					</mesh>
				</geometry>
			</collision>
			<visual name="visual">
				<geometry>
					<mesh>
						<uri>model://base/crank1_ad.stl</uri>
					</mesh>
				</geometry>
			</visual>
		</link>

		<joint name="base_to_d" type="revolute">
			<pose>0 0 0 0 0 0</pose>
			<child>d_crank_link</child>
			<parent>link_base</parent>
			<axis>
				<xyz>1 0 0</xyz>
				<use_parent_model_frame>1</use_parent_model_frame>
			</axis>
		</joint>

		<link name="asi_a_1">
			<pose>-0.0627 0.141830127 0.0105 0.78 0 0</pose>
			<self_collide>1</self_collide>
			<inertial>
				<pose>0.0044845 -0.00563879 -0.00377687 0 0 0</pose>
				<mass>0.010706</mass>
				<inertia>
					<ixx>0.000005401807</ixx>
					<ixy>0.000000000185</ixy>
					<ixz>0.000000000496</ixz>
					<iyy>0.000003139093</iyy>
					<iyz>-0.00000098431</iyz>
					<izz>0.000002411247</izz>
				</inertia>
			</inertial>
			<collision name="collision">
				<geometry>
					<mesh>
						<uri>model://base/asi.stl</uri>
					</mesh>
				</geometry>
			</collision>
			<visual name="visual">
				<geometry>
					<mesh>
						<uri>model://base/asi_ad.stl</uri>
					</mesh>
				</geometry>
			</visual>
		</link>

		<joint name="a_to_asi_1" type="revolute">
			<pose>0 0 0 0 0 0</pose>
			<child>asi_a_1</child>
			<parent>a_crank_link</parent>
			<axis>
				<xyz>1 0 0</xyz>
				<use_parent_model_frame>1</use_parent_model_frame>
			</axis>
		</joint>

		<link name="asi_a_2">
			<pose>-0.0447 0.1375 0.008 0.2199114858 0 0</pose>
			<self_collide>1</self_collide>
			<inertial>
				<pose>0.0044845 -0.00563879 -0.00377687 0 0 0</pose>
				<mass>0.010706</mass>
				<inertia>
					<ixx>0.000005401807</ixx>
					<ixy>0.000000000185</ixy>
					<ixz>0.000000000496</ixz>
					<iyy>0.000003139093</iyy>
					<iyz>-0.00000098431</iyz>
					<izz>0.000002411247</izz>
				</inertia>
			</inertial>
			<collision name="collision">
				<geometry>
					<mesh>
						<uri>model://base/asi.stl</uri>
					</mesh>
				</geometry>
			</collision>
			<visual name="visual">
				<geometry>
					<mesh>
						<uri>model://base/asi_ad.stl</uri>
					</mesh>
				</geometry>
			</visual>
		</link>

		<joint name="a_to_asi_2" type="revolute">
			<pose>0 0 0 0 0 0</pose>
			<child>asi_a_2</child>
			<parent>a_crank_link</parent>
			<axis>
				<xyz>1 0 0</xyz>
				<use_parent_model_frame>1</use_parent_model_frame>
			</axis>
		</joint>

		<link name="asi_a_3">
			<pose>-0.0257 0.13317 0.0105 -0.3909537524 0 0</pose>
			<self_collide>1</self_collide>
			<inertial>
				<pose>0.0044845 -0.00563879 -0.00377687 0 0 0</pose>
				<mass>0.010706</mass>
				<inertia>
					<ixx>0.000005401807</ixx>
					<ixy>0.000000000185</ixy>
					<ixz>0.000000000496</ixz>
					<iyy>0.000003139093</iyy>
					<iyz>-0.00000098431</iyz>
					<izz>0.000002411247</izz>
				</inertia>
			</inertial>
			<collision name="collision">
				<geometry>
					<mesh>
						<uri>model://base/asi.stl</uri>
					</mesh>
				</geometry>
			</collision>
			<visual name="visual">
				<geometry>
					<mesh>
						<uri>model://base/asi_ad.stl</uri>
					</mesh>
				</geometry>
			</visual>
		</link>

		<joint name="a_to_asi_3" type="revolute">
			<pose>0 0 0 0 0 0</pose>
			<child>asi_a_3</child>
			<parent>a_crank_link</parent>
			<axis>
				<xyz>1 0 0</xyz>
				<use_parent_model_frame>1</use_parent_model_frame>
			</axis>
		</joint>

	</model>
</sdf>
