<?xml version='1.0'?>
<sdf version="1.6">
<model name="base">
	<pose>0 0 0.1 0 0 0</pose>
	<static>false</static>
	<allow_auto_disable>1</allow_auto_disable>
		<link name="link_base">
			<pose>0 0 0 0 0 0</pose>
			<self_collide>1</self_collide>
			<must_be_base_link>1</must_be_base_link>
			<inertial>
				<pose>-0.12003 0.0885733 0.024818 0 0 0</pose>
				<mass>0.323853</mass>
				<inertia>
					<ixx>0.001101</ixx>
					<ixy>-0.000000019489</ixy>
					<ixz>-0.00000032811</ixz>
					<iyy>0.001144</iyy>
					<iyz>-0.00002903</iyz>
					<izz>0.001950</izz>
				</inertia>
			</inertial>
			<collision name="collision">
				<geometry>
					<mesh>
						<uri>model://base/base_blen_low_3.stl</uri>
					</mesh>
				</geometry>
				<surface>
					<friction>
						<torsional>
							<coefficient>0</coefficient>
						</torsional>
						<ode>
							<mu>0</mu>
							<mu2>0</mu2>
							<slip1>1.0</slip1>
							<slip2>1.0</slip2>
						</ode>
					</friction>
				</surface>
			</collision>
			<visual name="visual">
				<geometry>
					<mesh>
						<uri>model://base/base_blen_low_3.stl</uri>
					</mesh>
				</geometry>
				<material>
					<ambient>1 0.5 0 1</ambient>
					<diffuse>1 0.5 0 1</diffuse>
					<specular>0 0 0 0</specular>
					<emissive>0 0 0 1</emissive>
				</material>
			</visual>
		</link>

		<link name="a_crank_link">
			<pose>-0.0777 0.1375 0.013 0 0 0</pose>
			<inertial>
				<pose>0.037341 -0.000000002377 -0.002966 0 0 0</pose>
				<mass>0.111155</mass>
				<inertia>
					<ixx>0.00001696</ixx>
					<ixy>0.000005133807</ixy>
					<ixz>-0.000000043631</ixz>
					<iyy>0.00003475</iyy>
					<iyz>0.00002165</iyz>
					<izz>0.00003573</izz>
				</inertia>
			</inertial>
			<collision name="collision">
				<geometry>
					<mesh>
						<uri>model://base/crank1_collide_ad_blen_low2.stl</uri>
					</mesh>
				</geometry>
			</collision>
			<visual name="visual">
				<geometry>
					<mesh>
						<uri>model://base/crank1_collide_ad_blen_low2.stl</uri>
					</mesh>
				</geometry>
				<material>
					<ambient>0.6 0.6 0.6 1</ambient>
					<diffuse>0.6 0.6 0.6 1</diffuse>
					<specular>0 0 0 0</specular>
					<emissive>0 0 0 1</emissive>
				</material>
			</visual>
		</link>

		<joint name="base_to_a" type="revolute">
			<pose>0 0 0 0 0 0</pose>
			<child>a_crank_link</child>
			<parent>link_base</parent>
			<axis>
				<xyz>1 0 0</xyz>
				<use_parent_model_frame>1</use_parent_model_frame>
			</axis>
		</joint>

		<link name="b_crank_link">
			<pose>-0.1623 0.1375 0.013 0 0 0</pose>
			<inertial>
				<pose>-0.037341 -0.000000002377 -0.002966 0 0 0</pose>
				<mass>0.111155</mass>
				<inertia>
					<ixx>0.00001696</ixx>
					<ixy>-0.000005133807</ixy>
					<ixz>0.000000043631</ixz>
					<iyy>0.00003475</iyy>
					<iyz>-0.00002165</iyz>
					<izz>0.00003573</izz>
				</inertia>
			</inertial>
			<collision name="collision">
				<geometry>
					<mesh>
						<uri>model://base/crank2_collide_ad_blen_low2.stl</uri>
					</mesh>
				</geometry>
			</collision>
			<visual name="visual">
				<geometry>
					<mesh>
						<uri>model://base/crank2_collide_ad_blen_low2.stl</uri>
					</mesh>
				</geometry>
				<material>
					<ambient>0.6 0.6 0.6 1</ambient>
					<diffuse>0.6 0.6 0.6 1</diffuse>
					<specular>0 0 0 0</specular>
					<emissive>0 0 0 1</emissive>
				</material>
			</visual>
		</link>

		<joint name="base_to_b" type="revolute">
			<pose>0 0 0 0 0 0</pose>
			<child>b_crank_link</child>
			<parent>link_base</parent>
			<axis>
				<xyz>1 0 0</xyz>
				<use_parent_model_frame>1</use_parent_model_frame>
			</axis>
		</joint>

		<link name="c_crank_link">
			<pose>-0.1623 0.0475 0.013 0 0 0</pose>
			<inertial>
				<pose>-0.037341 -0.000000002377 -0.002966 0 0 0</pose>
				<mass>0.111155</mass>
				<inertia>
					<ixx>0.00001696</ixx>
					<ixy>-0.000005133807</ixy>
					<ixz>0.000000043631</ixz>
					<iyy>0.00003475</iyy>
					<iyz>-0.00002165</iyz>
					<izz>0.00003573</izz>
				</inertia>
			</inertial>
			<collision name="collision">
				<geometry>
					<mesh>
						<uri>model://base/crank2_collide_ad_blen_low2.stl</uri>
					</mesh>
				</geometry>
			</collision>
			<visual name="visual">
				<geometry>
					<mesh>
						<uri>model://base/crank2_collide_ad_blen_low2.stl</uri>
					</mesh>
				</geometry>
				<material>
					<ambient>0.6 0.6 0.6 1</ambient>
					<diffuse>0.6 0.6 0.6 1</diffuse>
					<specular>0 0 0 0</specular>
					<emissive>0 0 0 1</emissive>
				</material>
			</visual>
		</link>

		<joint name="base_to_c" type="revolute">
			<pose>0 0 0 0 0 0</pose>
			<child>c_crank_link</child>
			<parent>link_base</parent>
			<axis>
				<xyz>1 0 0</xyz>
				<use_parent_model_frame>1</use_parent_model_frame>
			</axis>
		</joint>

		<link name="d_crank_link">
			<pose>-0.0777 0.0475 0.013 0 0 0</pose>
			<inertial>
				<pose>0.037341 -0.000000002377 -0.002966 0 0 0</pose>
				<mass>0.111155</mass>
				<inertia>
					<ixx>0.00001696</ixx>
					<ixy>0.000005133807</ixy>
					<ixz>-0.000000043631</ixz>
					<iyy>0.00003475</iyy>
					<iyz>0.00002165</iyz>
					<izz>0.00003573</izz>
				</inertia>
			</inertial>
			<collision name="collision">
				<geometry>
					<mesh>
						<uri>model://base/crank1_collide_ad_blen_low2.stl</uri>
					</mesh>
				</geometry>
			</collision>
			<visual name="visual">
				<geometry>
					<mesh>
						<uri>model://base/crank1_collide_ad_blen_low2.stl</uri>
					</mesh>
				</geometry>
				<material>
					<ambient>0.6 0.6 0.6 1</ambient>
					<diffuse>0.6 0.6 0.6 1</diffuse>
					<specular>0 0 0 0</specular>
					<emissive>0 0 0 1</emissive>
				</material>
			</visual>
		</link>

		<joint name="base_to_d" type="revolute">
			<pose>0 0 0 0 0 0</pose>
			<child>d_crank_link</child>
			<parent>link_base</parent>
			<axis>
				<xyz>1 0 0</xyz>
				<use_parent_model_frame>1</use_parent_model_frame>
			</axis>
		</joint>
	

		<link name="asi_a_1">
			<pose>-0.0627 0.141830127 0.0105 0.78 0 0</pose>
			<self_collide>1</self_collide>
			<inertial>
				<pose>0.0044845 -0.00563879 -0.00377687 0 0 0</pose>
				<mass>0.010706</mass>
				<inertia>
					<ixx>0.000005401807</ixx>
					<ixy>0.000000000185</ixy>
					<ixz>0.000000000496</ixz>
					<iyy>0.000003139093</iyy>
					<iyz>-0.00000098431</iyz>
					<izz>0.000002411247</izz>
				</inertia>
			</inertial>
			<collision name="collision">
				<geometry>
					<mesh>
						<uri>model://base/asi_1_blen_low.stl</uri>
					</mesh>
				</geometry>
			</collision>
			<visual name="visual">
				<geometry>
					<mesh>
						<uri>model://base/asi_1_blen_low.stl</uri>
					</mesh>
				</geometry>
				<material>
					<ambient>0 1 0 1</ambient>
					<diffuse>0 1 0 1</diffuse>
					<specular>0 0 0 0</specular>
					<emissive>0 0 0 1</emissive>
				</material>
			</visual>
		</link>

		<joint name="a_to_asi_1" type="revolute">
			<pose>0 0 0 0 0 0</pose>
			<child>asi_a_1</child>
			<parent>a_crank_link</parent>
			<axis>
				<xyz>1 0 0</xyz>
				<use_parent_model_frame>1</use_parent_model_frame>
			</axis>
		</joint>

		<link name="asi_a_2">
			<pose>-0.0447 0.1375 0.008 0.2199114858 0 0</pose>
			<self_collide>1</self_collide>
			<inertial>
				<pose>0.0044845 -0.00563879 -0.00377687 0 0 0</pose>
				<mass>0.010706</mass>
				<inertia>
					<ixx>0.000005401807</ixx>
					<ixy>0.000000000185</ixy>
					<ixz>0.000000000496</ixz>
					<iyy>0.000003139093</iyy>
					<iyz>-0.00000098431</iyz>
					<izz>0.000002411247</izz>
				</inertia>
			</inertial>
			<collision name="collision">
				<geometry>
					<mesh>
						<uri>model://base/asi_1_blen_low.stl</uri>
					</mesh>
				</geometry>
			</collision>
			<visual name="visual">
				<geometry>
					<mesh>
						<uri>model://base/asi_1_blen_low.stl</uri>
					</mesh>
				</geometry>
				<material>
					<ambient>0 1 0 1</ambient>
					<diffuse>0 1 0 1</diffuse>
					<specular>0 0 0 0</specular>
					<emissive>0 0 0 1</emissive>
				</material>
			</visual>
		</link>

		<joint name="a_to_asi_2" type="revolute">
			<pose>0 0 0 0 0 0</pose>
			<child>asi_a_2</child>
			<parent>a_crank_link</parent>
			<axis>
				<xyz>1 0 0</xyz>
				<use_parent_model_frame>1</use_parent_model_frame>
			</axis>
		</joint>

		<link name="asi_a_3">
			<pose>-0.0257 0.13317 0.0105 -0.3909537524 0 0</pose>
			<self_collide>1</self_collide>
			<inertial>
				<pose>0.0044845 -0.00563879 -0.00377687 0 0 0</pose>
				<mass>0.010706</mass>
				<inertia>
					<ixx>0.000005401807</ixx>
					<ixy>0.000000000185</ixy>
					<ixz>0.000000000496</ixz>
					<iyy>0.000003139093</iyy>
					<iyz>-0.00000098431</iyz>
					<izz>0.000002411247</izz>
				</inertia>
			</inertial>
			<collision name="collision">
				<geometry>
					<mesh>
						<uri>model://base/asi_1_blen_low.stl</uri>
					</mesh>
				</geometry>
			</collision>
			<visual name="visual">
				<geometry>
					<mesh>
						<uri>model://base/asi_1_blen_low.stl</uri>
					</mesh>
				</geometry>
				<material>
					<ambient>0 1 0 1</ambient>
					<diffuse>0 1 0 1</diffuse>
					<specular>0 0 0 0</specular>
					<emissive>0 0 0 1</emissive>
				</material>
			</visual>
		</link>

		<joint name="a_to_asi_3" type="revolute">
			<pose>0 0 0 0 0 0</pose>
			<child>asi_a_3</child>
			<parent>a_crank_link</parent>
			<axis>
				<xyz>1 0 0</xyz>
				<use_parent_model_frame>1</use_parent_model_frame>
			</axis>
		</joint>


		<link name="asi_d_1">
			<pose>-0.0627 0.05183 0.0105 0.78 0 0</pose>
			<self_collide>1</self_collide>
			<inertial>
				<pose>0.0044845 -0.00563879 -0.00377687 0 0 0</pose>
				<mass>0.010706</mass>
				<inertia>
					<ixx>0.000005401807</ixx>
					<ixy>0.000000000185</ixy>
					<ixz>0.000000000496</ixz>
					<iyy>0.000003139093</iyy>
					<iyz>-0.00000098431</iyz>
					<izz>0.000002411247</izz>
				</inertia>
			</inertial>
			<collision name="collision">
				<geometry>
					<mesh>
						<uri>model://base/asi_1_blen_low.stl</uri>
					</mesh>
				</geometry>
			</collision>
			<visual name="visual">
				<geometry>
					<mesh>
						<uri>model://base/asi_1_blen_low.stl</uri>
					</mesh>
				</geometry>
				<material>
					<ambient>0 1 0 1</ambient>
					<diffuse>0 1 0 1</diffuse>
					<specular>0 0 0 0</specular>
					<emissive>0 0 0 1</emissive>
				</material>
			</visual>
		</link>

		<joint name="d_to_asi_1" type="revolute">
			<pose>0 0 0 0 0 0</pose>
			<child>asi_d_1</child>
			<parent>d_crank_link</parent>
			<axis>
				<xyz>1 0 0</xyz>
				<use_parent_model_frame>1</use_parent_model_frame>
			</axis>
		</joint>

		<link name="asi_d_2">
			<pose>-0.0447 0.0475 0.008 0.2199114858 0 0</pose>
			<self_collide>1</self_collide>
			<inertial>
				<pose>0.0044845 -0.00563879 -0.00377687 0 0 0</pose>
				<mass>0.010706</mass>
				<inertia>
					<ixx>0.000005401807</ixx>
					<ixy>0.000000000185</ixy>
					<ixz>0.000000000496</ixz>
					<iyy>0.000003139093</iyy>
					<iyz>-0.00000098431</iyz>
					<izz>0.000002411247</izz>
				</inertia>
			</inertial>
			<collision name="collision">
				<geometry>
					<mesh>
						<uri>model://base/asi_1_blen_low.stl</uri>
					</mesh>
				</geometry>
			</collision>
			<visual name="visual">
				<geometry>
					<mesh>
						<uri>model://base/asi_1_blen_low.stl</uri>
					</mesh>
				</geometry>
				<material>
					<ambient>0 1 0 1</ambient>
					<diffuse>0 1 0 1</diffuse>
					<specular>0 0 0 0</specular>
					<emissive>0 0 0 1</emissive>
				</material>
			</visual>
		</link>

		<joint name="d_to_asi_2" type="revolute">
			<pose>0 0 0 0 0 0</pose>
			<child>asi_d_2</child>
			<parent>d_crank_link</parent>
			<axis>
				<xyz>1 0 0</xyz>
				<use_parent_model_frame>1</use_parent_model_frame>
			</axis>
		</joint>

		<link name="asi_d_3">
			<pose>-0.0257 0.04317 0.0105 -0.3909537524 0 0</pose>
			<self_collide>1</self_collide>
			<inertial>
				<pose>0.0044845 -0.00563879 -0.00377687 0 0 0</pose>
				<mass>0.010706</mass>
				<inertia>
					<ixx>0.000005401807</ixx>
					<ixy>0.000000000185</ixy>
					<ixz>0.000000000496</ixz>
					<iyy>0.000003139093</iyy>
					<iyz>-0.00000098431</iyz>
					<izz>0.000002411247</izz>
				</inertia>
			</inertial>
			<collision name="collision">
				<geometry>
					<mesh>
						<uri>model://base/asi_1_blen_low.stl</uri>
					</mesh>
				</geometry>
			</collision>
			<visual name="visual">
				<geometry>
					<mesh>
						<uri>model://base/asi_1_blen_low.stl</uri>
					</mesh>
				</geometry>
				<material>
					<ambient>0 1 0 1</ambient>
					<diffuse>0 1 0 1</diffuse>
					<specular>0 0 0 0</specular>
					<emissive>0 0 0 1</emissive>
				</material>
			</visual>
		</link>

		<joint name="d_to_asi_3" type="revolute">
			<pose>0 0 0 0 0 0</pose>
			<child>asi_d_3</child>
			<parent>d_crank_link</parent>
			<axis>
				<xyz>1 0 0</xyz>
				<use_parent_model_frame>1</use_parent_model_frame>
			</axis>
		</joint>

		<link name="asi_b_1">
			<pose>-0.1773 0.141830127 0.0105 0.78 0 0</pose>
			<self_collide>1</self_collide>
			<inertial>
				<pose>-0.0045155 -0.00563879 -0.00377687 0 0 0</pose>
				<mass>0.010706</mass>
				<inertia>
					<ixx>0.000005401807</ixx>
					<ixy>0.000000000185</ixy>
					<ixz>0.000000000496</ixz>
					<iyy>0.000003139093</iyy>
					<iyz>-0.00000098431</iyz>
					<izz>0.000002411247</izz>
				</inertia>
			</inertial>
			<collision name="collision">
				<geometry>
					<mesh>
						<uri>model://base/asi_2_blen_low.stl</uri>
					</mesh>
				</geometry>
			</collision>
			<visual name="visual">
				<geometry>
					<mesh>
						<uri>model://base/asi_2_blen_low.stl</uri>
					</mesh>
				</geometry>
				<material>
					<ambient>0 1 0 1</ambient>
					<diffuse>0 1 0 1</diffuse>
					<specular>0 0 0 0</specular>
					<emissive>0 0 0 1</emissive>
				</material>
			</visual>
		</link>

		<joint name="b_to_asi_1" type="revolute">
			<pose>0 0 0 0 0 0</pose>
			<child>asi_b_1</child>
			<parent>b_crank_link</parent>
			<axis>
				<xyz>1 0 0</xyz>
				<use_parent_model_frame>1</use_parent_model_frame>
			</axis>
		</joint>

		<link name="asi_b_2">
			<pose>-0.1953 0.1375 0.008 0.2199114858 0 0</pose>
			<self_collide>1</self_collide>
			<inertial>
				<pose>-0.0045155 -0.00563879 -0.00377687 0 0 0</pose>
				<mass>0.010706</mass>
				<inertia>
					<ixx>0.000005401807</ixx>
					<ixy>0.000000000185</ixy>
					<ixz>0.000000000496</ixz>
					<iyy>0.000003139093</iyy>
					<iyz>-0.00000098431</iyz>
					<izz>0.000002411247</izz>
				</inertia>
			</inertial>
			<collision name="collision">
				<geometry>
					<mesh>
						<uri>model://base/asi_2_blen_low.stl</uri>
					</mesh>
				</geometry>
			</collision>
			<visual name="visual">
				<geometry>
					<mesh>
						<uri>model://base/asi_2_blen_low.stl</uri>
					</mesh>
				</geometry>
				<material>
					<ambient>0 1 0 1</ambient>
					<diffuse>0 1 0 1</diffuse>
					<specular>0 0 0 0</specular>
					<emissive>0 0 0 1</emissive>
				</material>
			</visual>
		</link>

		<joint name="b_to_asi_2" type="revolute">
			<pose>0 0 0 0 0 0</pose>
			<child>asi_b_2</child>
			<parent>b_crank_link</parent>
			<axis>
				<xyz>1 0 0</xyz>
				<use_parent_model_frame>1</use_parent_model_frame>
			</axis>
		</joint>

		<link name="asi_b_3">
			<pose>-0.2133 0.13317 0.0105 -0.3909537524 0 0</pose>
			<self_collide>1</self_collide>
			<inertial>
				<pose>-0.0045155 -0.00563879 -0.00377687 0 0 0</pose>
				<mass>0.010706</mass>
				<inertia>
					<ixx>0.000005401807</ixx>
					<ixy>0.000000000185</ixy>
					<ixz>0.000000000496</ixz>
					<iyy>0.000003139093</iyy>
					<iyz>-0.00000098431</iyz>
					<izz>0.000002411247</izz>
				</inertia>
			</inertial>
			<collision name="collision">
				<geometry>
					<mesh>
						<uri>model://base/asi_2_blen_low.stl</uri>
					</mesh>
				</geometry>
			</collision>
			<visual name="visual">
				<geometry>
					<mesh>
						<uri>model://base/asi_2_blen_low.stl</uri>
					</mesh>
				</geometry>
				<material>
					<ambient>0 1 0 1</ambient>
					<diffuse>0 1 0 1</diffuse>
					<specular>0 0 0 0</specular>
					<emissive>0 0 0 1</emissive>
				</material>
			</visual>
		</link>

		<joint name="b_to_asi_3" type="revolute">
			<pose>0 0 0 0 0 0</pose>
			<child>asi_b_3</child>
			<parent>b_crank_link</parent>
			<axis>
				<xyz>1 0 0</xyz>
				<use_parent_model_frame>1</use_parent_model_frame>
			</axis>
		</joint>

		<link name="asi_c_1">
			<pose>-0.1773 0.05183 0.0105 0.78 0 0</pose>
			<self_collide>1</self_collide>
			<inertial>
				<pose>-0.0045155 -0.00563879 -0.00377687 0 0 0</pose>
				<mass>0.010706</mass>
				<inertia>
					<ixx>0.000005401807</ixx>
					<ixy>0.000000000185</ixy>
					<ixz>0.000000000496</ixz>
					<iyy>0.000003139093</iyy>
					<iyz>-0.00000098431</iyz>
					<izz>0.000002411247</izz>
				</inertia>
			</inertial>
			<collision name="collision">
				<geometry>
					<mesh>
						<uri>model://base/asi_2_blen_low.stl</uri>
					</mesh>
				</geometry>
			</collision>
			<visual name="visual">
				<geometry>
					<mesh>
						<uri>model://base/asi_2_blen_low.stl</uri>
					</mesh>
				</geometry>
				<material>
					<ambient>0 1 0 1</ambient>
					<diffuse>0 1 0 1</diffuse>
					<specular>0 0 0 0</specular>
					<emissive>0 0 0 1</emissive>
				</material>
			</visual>
		</link>

		<joint name="c_to_asi_1" type="revolute">
			<pose>0 0 0 0 0 0</pose>
			<child>asi_c_1</child>
			<parent>c_crank_link</parent>
			<axis>
				<xyz>1 0 0</xyz>
				<use_parent_model_frame>1</use_parent_model_frame>
			</axis>
		</joint>

		<link name="asi_c_2">
			<pose>-0.1953 0.0475 0.008 0.2199114858 0 0</pose>
			<self_collide>1</self_collide>
			<inertial>
				<pose>-0.0045155 -0.00563879 -0.00377687 0 0 0</pose>
				<mass>0.010706</mass>
				<inertia>
					<ixx>0.000005401807</ixx>
					<ixy>0.000000000185</ixy>
					<ixz>0.000000000496</ixz>
					<iyy>0.000003139093</iyy>
					<iyz>-0.00000098431</iyz>
					<izz>0.000002411247</izz>
				</inertia>
			</inertial>
			<collision name="collision">
				<geometry>
					<mesh>
						<uri>model://base/asi_2_blen_low.stl</uri>
					</mesh>
				</geometry>
			</collision>
			<visual name="visual">
				<geometry>
					<mesh>
						<uri>model://base/asi_2_blen_low.stl</uri>
					</mesh>
				</geometry>
				<material>
					<ambient>0 1 0 1</ambient>
					<diffuse>0 1 0 1</diffuse>
					<specular>0 0 0 0</specular>
					<emissive>0 0 0 1</emissive>
				</material>
			</visual>
		</link>

		<joint name="c_to_asi_2" type="revolute">
			<pose>0 0 0 0 0 0</pose>
			<child>asi_c_2</child>
			<parent>c_crank_link</parent>
			<axis>
				<xyz>1 0 0</xyz>
				<use_parent_model_frame>1</use_parent_model_frame>
			</axis>
		</joint>

		<link name="asi_c_3">
			<pose>-0.2133 0.04317 0.0105 -0.3909537524 0 0</pose>
			<self_collide>1</self_collide>
			<inertial>
				<pose>-0.0045155 -0.00563879 -0.00377687 0 0 0</pose>
				<mass>0.010706</mass>
				<inertia>
					<ixx>0.000005401807</ixx>
					<ixy>0.000000000185</ixy>
					<ixz>0.000000000496</ixz>
					<iyy>0.000003139093</iyy>
					<iyz>-0.00000098431</iyz>
					<izz>0.000002411247</izz>
				</inertia>
			</inertial>
			<collision name="collision">
				<geometry>
					<mesh>
						<uri>model://base/asi_2_blen_low.stl</uri>
					</mesh>
				</geometry>
			</collision>
			<visual name="visual">
				<geometry>
					<mesh>
						<uri>model://base/asi_2_blen_low.stl</uri>
					</mesh>
				</geometry>
				<material>
					<ambient>0 1 0 1</ambient>
					<diffuse>0 1 0 1</diffuse>
					<specular>0 0 0 0</specular>
					<emissive>0 0 0 1</emissive>
				</material>
			</visual>
		</link>

		<joint name="c_to_asi_3" type="revolute">
			<pose>0 0 0 0 0 0</pose>
			<child>asi_c_3</child>
			<parent>c_crank_link</parent>
			<axis>
				<xyz>1 0 0</xyz>
				<use_parent_model_frame>1</use_parent_model_frame>
			</axis>
		</joint>

		<link name="imu_link">
			<pose>-0.127 0.0525 0.0605 0 0 0</pose>
			<inertial>
				<pose>0.007 -0.005 0.002135 0 0 0</pose>
				<mass>0.000403</mass>
				<inertia>
					<ixx>0.000000004476</ixx>
					<ixy>0.0</ixy>
					<ixz>0.0</ixz>
					<iyy>0.00000000567</iyy>
					<iyz>0.0</iyz>
					<izz>0.000000009696</izz>
				</inertia>
			</inertial>
			<collision name="collision">
				<geometry>
					<mesh>
						<uri>model://base/imu_sensor_low_ad.stl</uri>
					</mesh>
				</geometry>
			</collision>
			<visual name="visual">
				<geometry>
					<mesh>
						<uri>model://base/imu_sensor_low_ad.stl</uri>
					</mesh>
				</geometry>
			</visual>
			<sensor name="imu" type="imu">
				<pose>0.007 0.005 0.003 0 0 0</pose>
				<always_on>1</always_on>
				<plugin filename="libgazebo_ros_imu_sensor.so" name="imu_plugin">
					<robotNamespace>base</robotNamespace>
					<topicName>imu</topicName>
					<bodyName>imu_link</bodyName>
					<updateRateHZ>100.0</updateRateHZ>
					<gaussianNoise>0.0</gaussianNoise>
					<frameName>imu_link</frameName>
					<xyzOffset>0 0 0</xyzOffset>
        			<rpyOffset>0 -0 0</rpyOffset>
				</plugin>
			</sensor>
		</link>

		<joint name="imu_joint" type="fixed">
			<child>imu_link</child>
			<parent>link_base</parent>
		</joint>

		<link name="power_sup_link">
			<pose>-0.150 0.063 0.026 0 0 0</pose>
			<inertial>
				<pose>-0.0325 0.0335 0.0095</pose>
				<mass>0.129</mass>
				<inertia>
					<ixx>-0.0002102</ixx>
					<ixy>-0.0001415</ixy>
					<ixz>-0.00004014</ixz>
					<iyy>0.0001987</iyy>
					<iyz>-0.00004137</iyz>
					<izz>0.0003776</izz>
				</inertia>
			</inertial>
			<collision name="collision">
				<geometry>
					<mesh>
						<uri>model://base/power_supply_low_mesh_ad.stl</uri>
					</mesh>
				</geometry>
			</collision>
			<visual name="visual">
				<geometry>
					<mesh>
						<uri>model://base/power_supply_low_mesh_ad.stl</uri>
					</mesh>
				</geometry>
			</visual>
		</link>

		<joint name="power_sup_joint" type="fixed">
			<child>power_sup_link</child>
			<parent>link_base</parent>
		</joint>
		
		<plugin name="kame_controller" filename="libKamePlugin.so">
			<robotNamespace>base</robotNamespace>
      		<topic_name>cmd_velocity</topic_name>
      		<a_joint_name>base_to_a</a_joint_name>
      		<b_joint_name>base_to_b</b_joint_name>
      		<c_joint_name>base_to_c</c_joint_name>
      		<d_joint_name>base_to_d</d_joint_name>
   		</plugin>
	</model>
</sdf>
