<?xml version="1.0" encoding="utf-8"?>
<!-- =================================================================================== -->
<!-- |    This document was autogenerated by xacro from hekken.xacro                   | -->
<!-- |    EDITING THIS FILE BY HAND IS NOT RECOMMENDED                                 | -->
<!-- =================================================================================== -->
<robot name="hekken">
  <link name="base_link"/>
  <joint name="body_joint" type="fixed">
    <parent link="base_link"/>
    <child link="body_link"/>
    <origin rpy="0 0 0" xyz="0.0 0.0 0.05"/>
  </joint>
  <link name="body_link">
    <visual name="body">
      <geometry>
        <mesh filename="package://tokuken_robot_description/models/base/base_blen_low_3.stl"/>
      </geometry>
    </visual>
    <collision>
      <geometry>
        <mesh filename="package://tokuken_robot_description/models/base/base_blen_low_3.stl"/>
      </geometry>
    </collision>
    <inertial>
      <origin rpy="0 0 0" xyz="-0.12003 0.0885733 0.024818"/>
      <mass value="0.323853"/>
      <inertia ixx="0.001101" ixy="-0.000000019489" ixz="-0.00000032811" iyy="0.001144" iyz="-0.00002903" izz="0.001950"/>
    </inertial>
  </link>
  <gazebo reference="body_link">
    <material>Gazebo/Blue</material>
    <mu1 value="1.0"/>
    <mu2 value="1.0"/>
    <selfCollide>true</selfCollide>
  </gazebo>
  <joint name="b_crank_joint" type="continuous">
    <origin rpy="0 0 0" xyz="-0.1623 0.1375 0.013"/>
    <parent link="body_link"/>
    <child link="b_crank_link"/>
    <axis xyz="1 0 0"/>
    <limit effort="0.2" velocity="10.0"/>
    <dynamics damping="0.1"/>
  </joint>
  <transmission name="b_crank_move" type="SimpleTransmission">
    <type>transmission_interface/SimpleTransmission</type>
    <actuator name="b_crank_motor">
      <mechanicalReduction>1</mechanicalReduction>
    </actuator>
    <joint name="b_crank_joint">
      <hardwareInterface>hardware_interface/VelocityJointInterface</hardwareInterface>
    </joint>
  </transmission>
  <link name="b_crank_link">
    <visual>
      <geometry>
        <mesh filename="package://tokuken_robot_description/models/base/crank2_ad.stl"/>
        <!--<mesh filename="package://tokuken_robot_description/models/base/crank2_collide_ad_blen_low2.stl"/>-->
      </geometry>
      <material name="red">
        <color rgba="1.0 0.0 0.0 2.0"/>
      </material>
    </visual>
    <collision>
      <geometry>
        <mesh filename="package://tokuken_robot_description/models/base/crank2_ad.stl"/>
        <!--<mesh filename="package://tokuken_robot_description/models/base/crank2_collide_ad_blen_low2.stl"/>-->
      </geometry>
    </collision>
    <inertial>
      <origin rpy="0 0 0" xyz="-0.037341 -0.000000002377 -0.002966"/>
      <mass value="0.111155"/>
      <inertia ixx="0.00001696" ixy="-0.000005133807" ixz="0.000000043631" iyy="0.00003475" iyz="-0.00002165" izz="0.00003573"/>
    </inertial>
  </link>
  <gazebo reference="b_crank_link">
    <material>Gazebo/Red</material>
    <mu1 value="1.0"/>
    <mu2 value="1.0"/>
    <!--<selfCollide>true</selfCollide>-->
  </gazebo>
  <joint name="c_crank_joint" type="continuous">
    <origin rpy="0 0 0" xyz="-0.1623 0.0475 0.013"/>
    <parent link="body_link"/>
    <child link="c_crank_link"/>
    <axis xyz="1 0 0"/>
    <limit effort="0.2" velocity="10.0"/>
    <dynamics damping="0.1"/>
  </joint>
  <transmission name="c_crank_move" type="SimpleTransmission">
    <type>transmission_interface/SimpleTransmission</type>
    <actuator name="c_crank_motor">
      <mechanicalReduction>1</mechanicalReduction>
    </actuator>
    <joint name="c_crank_joint">
      <hardwareInterface>hardware_interface/VelocityJointInterface</hardwareInterface>
    </joint>
  </transmission>
  <link name="c_crank_link">
    <visual>
      <geometry>
        <mesh filename="package://tokuken_robot_description/models/base/crank2_ad.stl"/>
        <!--<mesh filename="package://tokuken_robot_description/models/base/crank2_collide_ad_blen_low2.stl"/>-->
      </geometry>
      <material name="red">
        <color rgba="1.0 0.0 0.0 2.0"/>
      </material>
    </visual>
    <collision>
      <geometry>
        <mesh filename="package://tokuken_robot_description/models/base/crank2_ad.stl"/>
        <!--<mesh filename="package://tokuken_robot_description/models/base/crank2_collide_ad_blen_low2.stl"/>-->
      </geometry>
    </collision>
    <inertial>
      <origin rpy="0 0 0" xyz="-0.037341 -0.000000002377 -0.002966"/>
      <mass value="0.111155"/>
      <inertia ixx="0.00001696" ixy="-0.000005133807" ixz="0.000000043631" iyy="0.00003475" iyz="-0.00002165" izz="0.00003573"/>
    </inertial>
  </link>
  <gazebo reference="c_crank_link">
    <material>Gazebo/Red</material>
    <mu1 value="1.0"/>
    <mu2 value="1.0"/>
    <!--<selfCollide>true</selfCollide>-->
  </gazebo>
  <joint name="d_crank_joint" type="continuous">
    <origin rpy="0 0 0" xyz="-0.0777 0.0475 0.013"/>
    <parent link="body_link"/>
    <child link="d_crank_link"/>
    <axis xyz="1 0 0"/>
    <limit effort="0.2" velocity="10.0"/>
    <dynamics damping="0.1"/>
  </joint>
  <transmission name="d_crank_move" type="SimpleTransmission">
    <type>transmission_interface/SimpleTransmission</type>
    <actuator name="d_crank_motor">
      <mechanicalReduction>1</mechanicalReduction>
    </actuator>
    <joint name="d_crank_joint">
      <hardwareInterface>hardware_interface/VelocityJointInterface</hardwareInterface>
    </joint>
  </transmission>
  <link name="d_crank_link">
    <visual>
      <geometry>
        <mesh filename="package://tokuken_robot_description/models/base/crank1_ad.stl"/>
        <!--<mesh filename="package://tokuken_robot_description/models/base/crank1_collide_ad_blen_low2.stl"/>-->
      </geometry>
      <material name="red"/>
    </visual>
    <collision>
      <geometry>
        <mesh filename="package://tokuken_robot_description/models/base/crank1_ad.stl"/>
        <!--<mesh filename="package://tokuken_robot_description/models/base/crank1_collide_ad_blen_low2.stl"/>-->
      </geometry>
    </collision>
    <inertial>
      <origin rpy="0 0 0" xyz="0.037341 -0.000000002377 -0.002966"/>
      <mass value="0.111155"/>
      <inertia ixx="0.00001696" ixy="0.000005133807" ixz="-0.000000043631" iyy="0.00003475" iyz="0.00002165" izz="0.00003573"/>
    </inertial>
  </link>
  <gazebo reference="d_crank_link">
    <material>Gazebo/Red</material>
    <mu1 value="1.0"/>
    <mu2 value="1.0"/>
    <!--<selfCollide>true</selfCollide>-->
  </gazebo>
  <joint name="a_crank_joint" type="continuous">
    <origin rpy="0 0 0" xyz="-0.0777 0.1375 0.013"/>
    <parent link="body_link"/>
    <child link="a_crank_link"/>
    <axis xyz="1 0 0"/>
    <limit effort="0.2" velocity="10.0"/>
    <dynamics damping="0.1"/>
  </joint>
  <transmission name="a_crank_move" type="SimpleTransmission">
    <type>transmission_interface/SimpleTransmission</type>
    <actuator name="a_crank_motor">
      <mechanicalReduction>1</mechanicalReduction>
    </actuator>
    <joint name="a_crank_joint">
      <hardwareInterface>hardware_interface/VelocityJointInterface</hardwareInterface>
    </joint>
  </transmission>
  <link name="a_crank_link">
    <visual>
      <geometry>
        <mesh filename="package://tokuken_robot_description/models/base/crank1_ad.stl"/>
        <!--<mesh filename="package://tokuken_robot_description/models/base/crank1_collide_ad_blen_low2.stl"/>-->
      </geometry>
      <material name="red"/>
    </visual>
    <collision>
      <geometry>
        <mesh filename="package://tokuken_robot_description/models/base/crank1_ad.stl"/>
        <!--<mesh filename="package://tokuken_robot_description/models/base/crank1_collide_ad_blen_low2.stl"/>-->
      </geometry>
    </collision>
    <inertial>
      <origin rpy="0 0 0" xyz="0.037341 -0.000000002377 -0.002966"/>
      <mass value="0.111155"/>
      <inertia ixx="0.00001696" ixy="0.000005133807" ixz="-0.000000043631" iyy="0.00003475" iyz="0.00002165" izz="0.00003573"/>
    </inertial>
  </link>
  <gazebo reference="a_crank_link">
    <material>Gazebo/Red</material>
    <mu1 value="1.0"/>
    <mu2 value="1.0"/>
    <!--<selfCollide>true</selfCollide>-->
  </gazebo>
  <joint name="b_asi_1_joint" type="continuous">
    <origin rpy="0.663225115758 0 0" xyz="-0.015 0.00433012701892 -0.0025"/>
    <parent link="b_crank_link"/>
    <child link="b_asi_1_link"/>
    <axis xyz="1 0 0"/>
  </joint>
  <link name="b_asi_1_link">
    <visual>
      <geometry>
        <mesh filename="package://tokuken_robot_description/models/base/asi_2_blen_low.stl"/>
      </geometry>
      <material name="green">
        <color rgba="0.0 0.0 1.0 2.0"/>
      </material>
    </visual>
    <collision>
      <geometry>
        <mesh filename="package://tokuken_robot_description/models/base/asi_2_blen_low.stl"/>
      </geometry>
    </collision>
    <inertial>
      <origin rpy="0 0 0" xyz="-0.0045155 -0.00563879 -0.00377687"/>
      <mass value="0.010706"/>
      <inertia ixx="0.000005401807" ixy="0.000000000185" ixz="0.000000000496" iyy="0.000003139093" iyz="-0.00000098431" izz="0.000002411247"/>
    </inertial>
  </link>
  <gazebo reference="b_asi_1_link">
    <material>Gazebo/Green</material>
    <mu1 value="1.0"/>
    <mu2 value="1.0"/>
    <selfCollide>true</selfCollide>
  </gazebo>
  <joint name="b_asi_2_joint" type="continuous">
    <origin rpy="0 0 0" xyz="-0.033 0.0 -0.005"/>
    <parent link="b_crank_link"/>
    <child link="b_asi_2_link"/>
    <axis xyz="1 0 0"/>
  </joint>
  <link name="b_asi_2_link">
    <visual>
      <geometry>
        <mesh filename="package://tokuken_robot_description/models/base/asi_2_blen_low.stl"/>
      </geometry>
      <material name="green">
        <color rgba="0.0 0.0 1.0 2.0"/>
      </material>
    </visual>
    <collision>
      <geometry>
        <mesh filename="package://tokuken_robot_description/models/base/asi_2_blen_low.stl"/>
      </geometry>
    </collision>
    <inertial>
      <origin rpy="0 0 0" xyz="-0.0045155 -0.00563879 -0.00377687"/>
      <mass value="0.010706"/>
      <inertia ixx="0.000005401807" ixy="0.000000000185" ixz="0.000000000496" iyy="0.000003139093" iyz="-0.00000098431" izz="0.000002411247"/>
    </inertial>
  </link>
  <gazebo reference="b_asi_2_link">
    <material>Gazebo/Green</material>
    <mu1 value="1.0"/>
    <mu2 value="1.0"/>
    <selfCollide>true</selfCollide>
  </gazebo>
  <joint name="b_asi_3_joint" type="continuous">
    <origin rpy="-0.645771823238 0 0" xyz="-0.051 -0.00433012701892 -0.0025"/>
    <parent link="b_crank_link"/>
    <child link="b_asi_3_link"/>
    <axis xyz="1 0 0"/>
  </joint>
  <link name="b_asi_3_link">
    <visual>
      <geometry>
        <mesh filename="package://tokuken_robot_description/models/base/asi_2_blen_low.stl"/>
      </geometry>
      <material name="green">
        <color rgba="0.0 0.0 1.0 2.0"/>
      </material>
    </visual>
    <collision>
      <geometry>
        <mesh filename="package://tokuken_robot_description/models/base/asi_2_blen_low.stl"/>
      </geometry>
    </collision>
    <inertial>
      <origin rpy="0 0 0" xyz="-0.0045155 -0.00563879 -0.00377687"/>
      <mass value="0.010706"/>
      <inertia ixx="0.000005401807" ixy="0.000000000185" ixz="0.000000000496" iyy="0.000003139093" iyz="-0.00000098431" izz="0.000002411247"/>
    </inertial>
  </link>
  <gazebo reference="b_asi_3_link">
    <material>Gazebo/Green</material>
    <mu1 value="1.0"/>
    <mu2 value="1.0"/>
    <selfCollide>true</selfCollide>
  </gazebo>
  <joint name="c_asi_1_joint" type="continuous">
    <origin rpy="0.663225115758 0 0" xyz="-0.015 0.00433012701892 -0.0025"/>
    <parent link="c_crank_link"/>
    <child link="c_asi_1_link"/>
    <axis xyz="1 0 0"/>
  </joint>
  <link name="c_asi_1_link">
    <visual>
      <geometry>
        <mesh filename="package://tokuken_robot_description/models/base/asi_2_blen_low.stl"/>
      </geometry>
      <material name="green">
        <color rgba="0.0 0.0 1.0 2.0"/>
      </material>
    </visual>
    <collision>
      <geometry>
        <mesh filename="package://tokuken_robot_description/models/base/asi_2_blen_low.stl"/>
      </geometry>
    </collision>
    <inertial>
      <origin rpy="0 0 0" xyz="-0.0045155 -0.00563879 -0.00377687"/>
      <mass value="0.010706"/>
      <inertia ixx="0.000005401807" ixy="0.000000000185" ixz="0.000000000496" iyy="0.000003139093" iyz="-0.00000098431" izz="0.000002411247"/>
    </inertial>
  </link>
  <gazebo reference="c_asi_1_link">
    <material>Gazebo/Green</material>
    <mu1 value="1.0"/>
    <mu2 value="1.0"/>
    <selfCollide>true</selfCollide>
  </gazebo>
  <joint name="c_asi_2_joint" type="continuous">
    <origin rpy="0 0 0" xyz="-0.033 0.0 -0.005"/>
    <parent link="c_crank_link"/>
    <child link="c_asi_2_link"/>
    <axis xyz="1 0 0"/>
  </joint>
  <link name="c_asi_2_link">
    <visual>
      <geometry>
        <mesh filename="package://tokuken_robot_description/models/base/asi_2_blen_low.stl"/>
      </geometry>
      <material name="green">
        <color rgba="0.0 0.0 1.0 2.0"/>
      </material>
    </visual>
    <collision>
      <geometry>
        <mesh filename="package://tokuken_robot_description/models/base/asi_2_blen_low.stl"/>
      </geometry>
    </collision>
    <inertial>
      <origin rpy="0 0 0" xyz="-0.0045155 -0.00563879 -0.00377687"/>
      <mass value="0.010706"/>
      <inertia ixx="0.000005401807" ixy="0.000000000185" ixz="0.000000000496" iyy="0.000003139093" iyz="-0.00000098431" izz="0.000002411247"/>
    </inertial>
  </link>
  <gazebo reference="c_asi_2_link">
    <material>Gazebo/Green</material>
    <mu1 value="1.0"/>
    <mu2 value="1.0"/>
    <selfCollide>true</selfCollide>
  </gazebo>
  <joint name="c_asi_3_joint" type="continuous">
    <origin rpy="-0.645771823238 0 0" xyz="-0.051 -0.00433012701892 -0.0025"/>
    <parent link="c_crank_link"/>
    <child link="c_asi_3_link"/>
    <axis xyz="1 0 0"/>
  </joint>
  <link name="c_asi_3_link">
    <visual>
      <geometry>
        <mesh filename="package://tokuken_robot_description/models/base/asi_2_blen_low.stl"/>
      </geometry>
      <material name="green">
        <color rgba="0.0 0.0 1.0 2.0"/>
      </material>
    </visual>
    <collision>
      <geometry>
        <mesh filename="package://tokuken_robot_description/models/base/asi_2_blen_low.stl"/>
      </geometry>
    </collision>
    <inertial>
      <origin rpy="0 0 0" xyz="-0.0045155 -0.00563879 -0.00377687"/>
      <mass value="0.010706"/>
      <inertia ixx="0.000005401807" ixy="0.000000000185" ixz="0.000000000496" iyy="0.000003139093" iyz="-0.00000098431" izz="0.000002411247"/>
    </inertial>
  </link>
  <gazebo reference="c_asi_3_link">
    <material>Gazebo/Green</material>
    <mu1 value="1.0"/>
    <mu2 value="1.0"/>
    <selfCollide>true</selfCollide>
  </gazebo>
  <joint name="a_asi_1_joint" type="continuous">
    <origin rpy="0.663225115758 0 0" xyz="0.015 0.00433012701892 -0.0025"/>
    <parent link="a_crank_link"/>
    <child link="a_asi_1_link"/>
    <axis xyz="1 0 0"/>
  </joint>
  <link name="a_asi_1_link">
    <visual>
      <geometry>
        <mesh filename="package://tokuken_robot_description/models/base/asi_1_blen_low.stl"/>
      </geometry>
      <material name="green"/>
    </visual>
    <collision>
      <geometry>
        <mesh filename="package://tokuken_robot_description/models/base/asi_1_blen_low.stl"/>
      </geometry>
    </collision>
    <inertial>
      <origin rpy="0 0 0" xyz="0.0044845 -0.00563879 -0.00377687"/>
      <mass value="0.010706"/>
      <inertia ixx="0.000005401807" ixy="0.000000000185" ixz="0.000000000496" iyy="0.000003139093" iyz="-0.00000098431" izz="0.000002411247"/>
    </inertial>
  </link>
  <gazebo reference="a_asi_1_link">
    <material>Gazebo/Green</material>
    <mu1 value="1.0"/>
    <mu2 value="1.0"/>
    <selfCollide>true</selfCollide>
  </gazebo>
  <joint name="a_asi_2_joint" type="continuous">
    <origin rpy="0 0 0" xyz="0.033 0.0 -0.005"/>
    <parent link="a_crank_link"/>
    <child link="a_asi_2_link"/>
    <axis xyz="1 0 0"/>
  </joint>
  <link name="a_asi_2_link">
    <visual>
      <geometry>
        <mesh filename="package://tokuken_robot_description/models/base/asi_1_blen_low.stl"/>
      </geometry>
      <material name="green"/>
    </visual>
    <collision>
      <geometry>
        <mesh filename="package://tokuken_robot_description/models/base/asi_1_blen_low.stl"/>
      </geometry>
    </collision>
    <inertial>
      <origin rpy="0 0 0" xyz="0.0044845 -0.00563879 -0.00377687"/>
      <mass value="0.010706"/>
      <inertia ixx="0.000005401807" ixy="0.000000000185" ixz="0.000000000496" iyy="0.000003139093" iyz="-0.00000098431" izz="0.000002411247"/>
    </inertial>
  </link>
  <gazebo reference="a_asi_2_link">
    <material>Gazebo/Green</material>
    <mu1 value="1.0"/>
    <mu2 value="1.0"/>
    <selfCollide>true</selfCollide>
  </gazebo>
  <joint name="a_asi_3_joint" type="continuous">
    <origin rpy="-0.645771823238 0 0" xyz="0.051 -0.00433012701892 -0.0025"/>
    <parent link="a_crank_link"/>
    <child link="a_asi_3_link"/>
    <axis xyz="1 0 0"/>
  </joint>
  <link name="a_asi_3_link">
    <visual>
      <geometry>
        <mesh filename="package://tokuken_robot_description/models/base/asi_1_blen_low.stl"/>
      </geometry>
      <material name="green"/>
    </visual>
    <collision>
      <geometry>
        <mesh filename="package://tokuken_robot_description/models/base/asi_1_blen_low.stl"/>
      </geometry>
    </collision>
    <inertial>
      <origin rpy="0 0 0" xyz="0.0044845 -0.00563879 -0.00377687"/>
      <mass value="0.010706"/>
      <inertia ixx="0.000005401807" ixy="0.000000000185" ixz="0.000000000496" iyy="0.000003139093" iyz="-0.00000098431" izz="0.000002411247"/>
    </inertial>
  </link>
  <gazebo reference="a_asi_3_link">
    <material>Gazebo/Green</material>
    <mu1 value="1.0"/>
    <mu2 value="1.0"/>
    <selfCollide>true</selfCollide>
  </gazebo>
  <joint name="d_asi_1_joint" type="continuous">
    <origin rpy="0.663225115758 0 0" xyz="0.015 0.00433012701892 -0.0025"/>
    <parent link="d_crank_link"/>
    <child link="d_asi_1_link"/>
    <axis xyz="1 0 0"/>
  </joint>
  <link name="d_asi_1_link">
    <visual>
      <geometry>
        <mesh filename="package://tokuken_robot_description/models/base/asi_1_blen_low.stl"/>
      </geometry>
      <material name="green"/>
    </visual>
    <collision>
      <geometry>
        <mesh filename="package://tokuken_robot_description/models/base/asi_1_blen_low.stl"/>
      </geometry>
    </collision>
    <inertial>
      <origin rpy="0 0 0" xyz="0.0044845 -0.00563879 -0.00377687"/>
      <mass value="0.010706"/>
      <inertia ixx="0.000005401807" ixy="0.000000000185" ixz="0.000000000496" iyy="0.000003139093" iyz="-0.00000098431" izz="0.000002411247"/>
    </inertial>
  </link>
  <gazebo reference="d_asi_1_link">
    <material>Gazebo/Green</material>
    <mu1 value="1.0"/>
    <mu2 value="1.0"/>
    <selfCollide>true</selfCollide>
  </gazebo>
  <joint name="d_asi_2_joint" type="continuous">
    <origin rpy="0 0 0" xyz="0.033 0.0 -0.005"/>
    <parent link="d_crank_link"/>
    <child link="d_asi_2_link"/>
    <axis xyz="1 0 0"/>
  </joint>
  <link name="d_asi_2_link">
    <visual>
      <geometry>
        <mesh filename="package://tokuken_robot_description/models/base/asi_1_blen_low.stl"/>
      </geometry>
      <material name="green"/>
    </visual>
    <collision>
      <geometry>
        <mesh filename="package://tokuken_robot_description/models/base/asi_1_blen_low.stl"/>
      </geometry>
    </collision>
    <inertial>
      <origin rpy="0 0 0" xyz="0.0044845 -0.00563879 -0.00377687"/>
      <mass value="0.010706"/>
      <inertia ixx="0.000005401807" ixy="0.000000000185" ixz="0.000000000496" iyy="0.000003139093" iyz="-0.00000098431" izz="0.000002411247"/>
    </inertial>
  </link>
  <gazebo reference="d_asi_2_link">
    <material>Gazebo/Green</material>
    <mu1 value="1.0"/>
    <mu2 value="1.0"/>
    <selfCollide>true</selfCollide>
  </gazebo>
  <joint name="d_asi_3_joint" type="continuous">
    <origin rpy="-0.645771823238 0 0" xyz="0.051 -0.00433012701892 -0.0025"/>
    <parent link="d_crank_link"/>
    <child link="d_asi_3_link"/>
    <axis xyz="1 0 0"/>
  </joint>
  <link name="d_asi_3_link">
    <visual>
      <geometry>
        <mesh filename="package://tokuken_robot_description/models/base/asi_1_blen_low.stl"/>
      </geometry>
      <material name="green"/>
    </visual>
    <collision>
      <geometry>
        <mesh filename="package://tokuken_robot_description/models/base/asi_1_blen_low.stl"/>
      </geometry>
    </collision>
    <inertial>
      <origin rpy="0 0 0" xyz="0.0044845 -0.00563879 -0.00377687"/>
      <mass value="0.010706"/>
      <inertia ixx="0.000005401807" ixy="0.000000000185" ixz="0.000000000496" iyy="0.000003139093" iyz="-0.00000098431" izz="0.000002411247"/>
    </inertial>
  </link>
  <gazebo reference="d_asi_3_link">
    <material>Gazebo/Green</material>
    <mu1 value="1.0"/>
    <mu2 value="1.0"/>
    <selfCollide>true</selfCollide>
  </gazebo>
  <gazebo>
    <plugin filename="libgazebo_ros_control.so" name="gazebo_ros_control">
      <robotNamespace>/hekken</robotNamespace>
      <robotSimType>gazebo_ros_control/DefaultRobotHWSim</robotSimType>
      <legacyModeNS>true</legacyModeNS>
    </plugin>
  </gazebo>
</robot>

