<?xml version="1.0"?>

<robot name="tokuken_robot_b">
	<link name="base_link">
		<visual>
			<geometry>
				<mesh filename="package://tokuken_robot_description/meshes/base_ad.stl" />
			</geometry>
			<material name="red">
				<color rgba="0.5 0 0 1" />
			</material>
		</visual>
		<collision>
			<geometry>
				<mesh filename="package://tokuken_robot_description/meshes/base_ad.stl" />
			</geometry>
		</collision>
		<inertial>
        	<mass value="0.323853"/>
        	<inertia ixx="0.003842" ixy="0.003443" ixz="-0.0009651" iyx="0.003443" iyy="0.006009" iyz="0.0006829" izx="-0.0009651" izy="0.0006829" izz="0.009156"/>
      	</inertial>
	</link>
	<gazebo reference="base_link">
		<material>Gazebo/Red</material>
	</gazebo>

	<link name="a_crank_link">
		<visual>
			<geometry>
				<mesh filename="package://tokuken_robot_description/meshes/crank1_ad.stl" />
			</geometry>
			<material name="green">
				<color rgba="0 0.7 0 1" />
			</material>
		</visual>
		<collision>
			<geometry>
				<mesh filename="package://tokuken_robot_description/meshes/crank1_ad.stl" />
			</geometry>
		</collision>
		<inertial>
        	<mass value="0.094516"/><!--mi-shusei-->
        	<inertia ixx="0.00001712" ixy="0.000006524249" ixz="-0.00001021" iyx="0.000006524249" iyy="0.0001625" iyz="-0.000000000112" izx="-0.00001021" izy="-0.000000000112" izz="0.0001625"/>
      	</inertial>
	</link>

	<link name="d_crank_link">
		<visual>
			<geometry>
				<mesh filename="package://tokuken_robot_description/meshes/crank1_ad.stl" />
			</geometry>
			<material name="green">
				<color rgba="0 0.7 0 1" />
			</material>
		</visual>
		<collision>
			<geometry>
				<mesh filename="package://tokuken_robot_description/meshes/crank1_ad.stl" />
			</geometry>
		</collision>
		<inertial>
        	<mass value="0.094516"/><!--mi-shusei-->
        	<inertia ixx="0.00001712" ixy="0.000006524249" ixz="-0.00001021" iyx="0.000006524249" iyy="0.0001625" iyz="-0.000000000112" izx="-0.00001021" izy="-0.000000000112" izz="0.0001625"/>
      	</inertial>
	</link>

	<link name="b_crank_link">
		<visual>
			<geometry>
				<mesh filename="package://tokuken_robot_description/meshes/crank2_ad.stl" />
			</geometry>
			<material name="green">
				<color rgba="0 0.7 0 1" />
			</material>
		</visual>
		<collision>
			<geometry>
				<mesh filename="package://tokuken_robot_description/meshes/crank2_ad.stl" />
			</geometry>
		</collision>
		<inertial>
        	<mass value="0.94516"/><!--mi-shusei-->
        	<inertia ixx="0.00001712" ixy="0.000006524249" ixz="0.00001119" iyx="-0.000004651619" iyy="0.0001625" iyz="0.0000000000000006756" izx="0.00001119" izy="0.0000000000000006756" izz="0.0001625"/>
      	</inertial>
	</link>

	<link name="c_crank_link">
		<visual>
			<geometry>
				<mesh filename="package://tokuken_robot_description/meshes/crank2_ad.stl" />
			</geometry>
			<material name="green">
				<color rgba="0 0.7 0 1" />
			</material>
		</visual>
		<collision>
			<geometry>
				<mesh filename="package://tokuken_robot_description/meshes/crank2_ad.stl" />
			</geometry>
		</collision>
		<inertial>
        	<mass value="0.94516"/><!--mi-shusei-->
        	<inertia ixx="0.00001712" ixy="0.000006524249" ixz="0.00001119" iyx="-0.000004651619" iyy="0.0001625" iyz="0.0000000000000006756" izx="0.00001119" izy="0.0000000000000006756" izz="0.0001625"/>
      	</inertial>
	</link>

	<link name="a_1_asi_link">
		<visual>
			<geometry>
				<mesh filename="package://tokuken_robot_description/meshes/asi_ad.stl" />
			</geometry>
			<material name="blue">
				<color rgba="0 0 0.7 1" />
			</material>
		</visual>
		<collision>
			<geometry>
				<mesh filename="package://tokuken_robot_description/meshes/asi_ad.stl" />
			</geometry>
		</collision>
		<inertial>
        	<mass value="0.010706"/><!--tekitou-->
        	<inertia ixx="0.000005894918" ixy="0.000000270901" ixz="-0.00000018083" iyx="0.000000270901" iyy="0.000003507106" iyz="-0.000000756312" izx="-0.00000018083" izy="-0.000000756312" izz="0.000002966943"/>
      	</inertial>
	</link>

	<joint name="base_to_a" type="continuous">
		<parent link="base_link"/>
		<child link="a_crank_link"/>
		<origin xyz="-0.0777 0.1375 0.013" rpy="0 0 0"/>
		<axis xyz="1 0 0"/>
	</joint>

	<joint name="base_to_d" type="continuous">
		<parent link="base_link"/>
		<child link="d_crank_link"/>
		<origin xyz="-0.0777 0.0475 0.013" rpy="0 0 0"/>
		<axis xyz="1 0 0"/>
	</joint>

	<joint name="base_to_b" type="continuous">
		<parent link="base_link"/>
		<child link="b_crank_link"/>
		<origin xyz="-0.1623 0.1375 0.013" rpy="0 0 0"/>
		<axis xyz="1 0 0"/>
	</joint>

	<joint name="base_to_c" type="continuous">
		<parent link="base_link"/>
		<child link="c_crank_link"/>
		<origin xyz="-0.1623 0.0475 0.013" rpy="0 0 0"/>
		<axis xyz="1 0 0"/>
	</joint>

	<joint name="a_to_asi_1" type="continuous">
		<parent link="a_crank_link"/>
		<child link="a_1_asi_link"/>
		<origin xyz="0.015 0.004330127019 -0.0025" rpy="0 0 0"/>
		<axis xyz="1 0 0"/>
		<limit velocity="40.0" effort="3.0" />
	</joint>

</robot>
